<?xml version="1.0" encoding="utf-8"?>
<!-- This URDF was automatically created by SolidWorks to URDF Exporter! Originally created by Stephen Brawner (brawner@gmail.com) 
     Commit Version: 1.5.1-0-g916b5db  Build Version: 1.5.7152.31018
     For more information, please see http://wiki.ros.org/sw_urdf_exporter -->
<robot
  name="Arm_basis">


 <!-- Joints Control in Gazebo -->
  <gazebo>
    <plugin name="gazebo_ros_control" filename="libgazebo_ros_control.so"/>
  </gazebo>



  <link 
	  name="world"/>

  <link
    name="base_link">
    <inertial>
      <origin
        xyz="1.2634E-17 0.42198 -7.7392E-18"
        rpy="0 0 0" />
      <mass
        value="34.843" />
      <inertia
        ixx="2.1897"
        ixy="-9.7311E-18"
        ixz="1.4022E-18"
        iyy="0.24101"
        iyz="-5.8141E-18"
        izz="2.1897" />
    </inertial>
    <visual>
      <origin
        xyz="0 0 0"
        rpy="0 0 0" />
      <geometry>
        <mesh
          filename="package://Arm_basis/meshes/base_link.STL" />
      </geometry>
      <material
        name="">
        <color
          rgba="1 1 1 1" />
      </material>
    </visual>
    <collision>
      <origin
        xyz="0 0 0"
        rpy="0 0 0" />
      <geometry>
        <mesh
          filename="package://Arm_basis/meshes/base_link.STL" />
      </geometry>
    </collision>
  </link>

  <link
    name="L1">
    <inertial>
      <origin
        xyz="2.6604E-17 0.02786 -1.9828E-17"
        rpy="0 0 0" />
      <mass
        value="0.72919" />
      <inertia
        ixx="0.0013291"
        ixy="-1.1635E-19"
        ixz="5.3363E-20"
        iyy="0.0024283"
        iyz="-6.7654E-20"
        izz="0.0017056" />
    </inertial>
    <visual>
      <origin
        xyz="0 0 0"
        rpy="0 0 0" />
      <geometry>
        <mesh
          filename="package://Arm_basis/meshes/L1.STL" />
      </geometry>
      <material
        name="">
        <color
          rgba="1 0.93725 0.13725 1" />
      </material>
    </visual>
    <collision>
      <origin
        xyz="0 0 0"
        rpy="0 0 0" />
      <geometry>
        <mesh
          filename="package://Arm_basis/meshes/L1.STL" />
      </geometry>
    </collision>
  </link>
  
  <joint 
    name="fixed"
    type="fixed">
    <origin
      xyz="0 0 0"
      />
    <parent
      link="world" />
    <child
      link="base_link"/>
  
</joint>  
  
  <joint
    name="J0"
    type="revolute">
    <origin
      xyz="0 0 0.83"
      rpy="1.5708 0 -3.1327" />
    <parent
      link="base_link" />
    <child
      link="L1" />
    <axis
      xyz="0 1 0" />
    <limit
      lower="-3.142"
      upper="3.142"
      effort="0"
      velocity="0.2" />
  </joint>
  <link
    name="L2">
    <inertial>
      <origin
        xyz="0.21787 -4.4409E-16 -5.1277E-18"
        rpy="0 0 0" />
      <mass
        value="2.8363" />
      <inertia
        ixx="0.010262"
        ixy="1.1015E-16"
        ixz="-2.4137E-17"
        iyy="0.06642"
        iyz="-1.1032E-17"
        izz="0.059986" />
    </inertial>
    <visual>
      <origin
        xyz="0 0 0"
        rpy="0 0 0" />
      <geometry>
        <mesh
          filename="package://Arm_basis/meshes/L2.STL" />
      </geometry>
      <material
        name="">
        <color
          rgba="0.89804 0.91765 0.92941 1" />
      </material>
    </visual>
    <collision>
      <origin
        xyz="0 0 0"
        rpy="0 0 0" />
      <geometry>
        <mesh
          filename="package://Arm_basis/meshes/L2.STL" />
      </geometry>
    </collision>
  </link>i


  <joint
    name="J1"
    type="revolute">
    <origin
      xyz="0 0.0781 0"
      rpy="1.5708 0.68191 1.5708" />
    <parent
      link="L1" />
    <child
      link="L2" />
    <axis
      xyz="0 0 -1" />
    <limit
      lower="-3.142"
      upper="3.142"
      effort="0"
      velocity="0.2" />
  </joint>
  <link
    name="L3">
    <inertial>
      <origin
        xyz="4.4409E-16 0.10085 0.0019"
        rpy="0 0 0" />
      <mass
        value="1.2325" />
      <inertia
        ixx="0.010475"
        ixy="-4.7739E-17"
        ixz="7.9071E-19"
        iyy="0.0018442"
        iyz="-5.9462E-19"
        izz="0.010442" />
    </inertial>
    <visual>
      <origin
        xyz="0 0 0"
        rpy="0 0 0" />
      <geometry>
        <mesh
          filename="package://Arm_basis/meshes/L3.STL" />
      </geometry>
      <material
        name="">
        <color
          rgba="1 0.93725 0.13725 1" />
      </material>
    </visual>
    <collision>
      <origin
        xyz="0 0 0"
        rpy="0 0 0" />
      <geometry>
        <mesh
          filename="package://Arm_basis/meshes/L3.STL" />
      </geometry>
    </collision>
  </link>
  <joint
    name="J2"
    type="revolute">
    <origin
      xyz="0.4238 0 0"
      rpy="-3.1416 0 0.66365" />
    <parent
      link="L2" />
    <child
      link="L3" />
    <axis
      xyz="0 0 1" />
    <limit
      lower="-3.142"
      upper="3.142"
      effort="0"
      velocity="0.2" />
  </joint>

  <transmission name="tran0">
    <type>transmission_interface/SimpleTransmission</type>
    <joint name="J0">
      <hardwareInterface>hardware_interface/EffortJointInterface</hardwareInterface>
    </joint>
    <actuator name="motor0">
      <hardwareInterface>hardware_interface/EffortJointInterface</hardwareInterface>
      <mechanicalReduction>1</mechanicalReduction>
    </actuator>
  </transmission>

  <transmission name="tran1">
    <type>transmission_interface/SimpleTransmission</type>
    <joint name="J1">
      <hardwareInterface>hardware_interface/EffortJointInterface</hardwareInterface>
    </joint>
    <actuator name="motor1">
      <hardwareInterface>hardware_interface/EffortJointInterface</hardwareInterface>
      <mechanicalReduction>1</mechanicalReduction>
    </actuator>
  </transmission>

    <transmission name="tran2">
    <type>transmission_interface/SimpleTransmission</type>
    <joint name="J2">
      <hardwareInterface>hardware_interface/EffortJointInterface</hardwareInterface>
    </joint>
    <actuator name="motor2">
      <hardwareInterface>hardware_interface/EffortJointInterface</hardwareInterface>
      <mechanicalReduction>1</mechanicalReduction>
    </actuator>
  </transmission>







</robot>


