<?xml version="1.0" encoding="utf-8" ?>
<!-- This URDF was automatically created by SolidWorks to URDF Exporter! Originally created by Stephen Brawner (brawner@gmail.com) 
     Commit Version: 1.5.1-0-g916b5db  Build Version: 1.5.7152.31018
     For more information, please see http://wiki.ros.org/sw_urdf_exporter -->
<robot name="arm_description">
  
    
    <link name="world">
    </link>

    <gazebo>
    <plugin name="gazebo_ros_control" filename="libgazebo_ros_control.so">
        <robotNamespace>/</robotNamespace>
    </plugin>
</gazebo>

    <link name="base_link">
        
<inertial>
            <origin xyz="0.046889 0.00049452 -0.3168" rpy="0 0 0" />
            <mass value="29.988" />
            <inertia ixx="3.9577" ixy="-0.00084235" ixz="-0.074162" iyy="4.2269" iyz="-0.012306" izz="1.777" />
        </inertial>

        <visual>
            <origin xyz="0 0 0" rpy="0 0 0" />
            <geometry>
                <mesh filename="package://arm_description/meshes/base_link.STL" />
            </geometry>
            <material name="">
                <color rgba="0.79216 0.81961 0.93333 1" />
            </material>
        </visual>
        <collision>
            <origin xyz="0 0 0" rpy="0 0 0" />
            <geometry>
                <mesh filename="package://arm_description/meshes/base_link.STL" />
            </geometry>
        </collision>
    </link>


    <joint name="fixed" type="fixed">
        <origin xyz="0 0 0"  />
        <parent link="world" />
        <child link="base_link" />
    </joint>

    <link name="Link0">
        
<inertial>
            <origin xyz="-0.091685 7.9817E-06 0.039528" rpy="0 0 0" />
            <mass value="0.94745" />
            <inertia ixx="0.0017212" ixy="-9.0051E-07" ixz="5.6302E-05" iyy="0.0021872" iyz="4.5068E-07" izz="0.0035384" />
        </inertial>

        <visual>
            <origin xyz="0 0 0" rpy="0 0 0" />
            <geometry>
                <mesh filename="package://arm_description/meshes/Link0.STL" />
            </geometry>
            <material name="">
                <color rgba="0.6 0.6 0.6 1" />
            </material>
        </visual>
        <collision>
            <origin xyz="0 0 0" rpy="0 0 0" />
            <geometry>
                <mesh filename="package://arm_description/meshes/Link0.STL" />
            </geometry>
        </collision>
    </link>
    <joint name="J0" type="fixed">
        <origin xyz="0.055058 0 0.00635" rpy="0 0 0" />
        <parent link="base_link" />
        <child link="Link0" />
        <axis xyz="0 0 0" />
    </joint>
    <link name="Link1">
        
<inertial>
            <origin xyz="0.052938 -0.0202 0.11556" rpy="0 0 0" />
            <mass value="0.7296" />
            <inertia ixx="0.00048256" ixy="4.274E-06" ixz="-3.5713E-05" iyy="0.00068662" iyz="2.2504E-06" izz="0.00049478" />
        </inertial>

        <visual>
            <origin xyz="0 0 0" rpy="0 0 0" />
            <geometry>
                <mesh filename="package://arm_description/meshes/Link1.STL" />
            </geometry>
            <material name="">
                <color rgba="0.66667 0.69804 0.76863 1" />
            </material>
        </visual>
        <collision>
            <origin xyz="0 0 0" rpy="0 0 0" />
            <geometry>
                <mesh filename="package://arm_description/meshes/Link1.STL" />
            </geometry>
        </collision>
    </link>
    <joint name="J1" type="revolute">
        <origin xyz="0 0 0.0307" rpy="0 0 0" />
        <parent link="Link0" />
        <child link="Link1" />
        <axis xyz="0 0 1" />
        <limit lower="-3.14" upper="3.14" effort="1" velocity="0.2" />
       <!-- <dynamics damping="1" friction="1" /> -->
    </joint>
    <link name="Link2">
        
<inertial>
            <origin xyz="-0.0016902 -0.0051417 0.14919" rpy="0 0 0" />
            <mass value="0.64235" />
            <inertia ixx="0.0026795" ixy="1.0388E-07" ixz="5.9339E-06" iyy="0.0028646" iyz="-1.0172E-07" izz="0.00025998" />
        </inertial>

        <visual>
            <origin xyz="0 0 0" rpy="0 0 0" />
            <geometry>
                <mesh filename="package://arm_description/meshes/Link2.STL" />
            </geometry>
            <material name="">
                <color rgba="0.6 0.6 0.6 1" />
            </material>
        </visual>
        <collision>
            <origin xyz="0 0 0" rpy="0 0 0" />
            <geometry>
                <mesh filename="package://arm_description/meshes/Link2.STL" />
            </geometry>
        </collision>
    </link>
    <joint name="J2" type="revolute">
        <origin xyz="0.064146 0.051713 0.13908" rpy="0 0 0" />
        <parent link="Link1" />
        <child link="Link2" />
        <axis xyz="0 1 0" />
        <limit lower="-3.14" upper="3.14" effort="1" velocity="0.2" />
        <!-- <dynamics damping="1" friction="1" /> -->
    </joint>
    <link name="Link3">
        
<inertial>
            <origin xyz="-0.015301 -0.033924 -0.019018" rpy="0 0 0" />
            <mass value="0.25905" />
            <inertia ixx="7.1842E-05" ixy="-2.2078E-06" ixz="4.0076E-07" iyy="0.00022797" iyz="6.1732E-08" izz="0.00023684" />
        </inertial>

        <visual>
            <origin xyz="0 0 0" rpy="0 0 0" />
            <geometry>
                <mesh filename="package://arm_description/meshes/Link3.STL" />
            </geometry>
            <material name="">
                <color rgba="0.66667 0.69804 0.76863 1" />
            </material>
        </visual>
        <collision>
            <origin xyz="0 0 0" rpy="0 0 0" />
            <geometry>
                <mesh filename="package://arm_description/meshes/Link3.STL" />
            </geometry>
        </collision>
    </link>
    <joint name="J3" type="revolute">
        <origin xyz="0 -0.015 0.305" rpy="0 0 0" />
        <parent link="Link2" />
        <child link="Link3" />
        <axis xyz="0 -1 0" />
        <limit lower="-3.14" upper="3.14" effort="1" velocity="0.2" />
        <!-- <dynamics damping="1" friction="1" /> -->
    </joint>
    <link name="Link4">
        
<inertial>
            <origin xyz="0.094357 -0.0036851 0.0014509" rpy="0 0 0" />
            <mass value="0.26849" />
            <inertia ixx="9.7347E-05" ixy="4.5376E-06" ixz="1.4747E-05" iyy="0.00057145" iyz="-1.9226E-06" izz="0.00051253" />
        </inertial>

        <visual>
            <origin xyz="0 0 0" rpy="0 0 0" />
            <geometry>
                <mesh filename="package://arm_description/meshes/Link4.STL" />
            </geometry>
            <material name="">
                <color rgba="0.66667 0.69804 0.76863 1" />
            </material>
        </visual>
        <collision>
            <origin xyz="0 0 0" rpy="0 0 0" />
            <geometry>
                <mesh filename="package://arm_description/meshes/Link4.STL" />
            </geometry>
        </collision>
    </link>
    <joint name="J4" type="revolute">
        <origin xyz="0.035639 -0.0367 0" rpy="0 0 0" />
        <parent link="Link3" />
        <child link="Link4" />
        <axis xyz="-1 0 0" />
        <limit lower="-3.14" upper="3.14" effort="1" velocity="0.2" />
         <dynamics damping="0.5" friction="0.5" /> 
    </joint>
    <link name="Link5">
        
<inertial>
            <origin xyz="-0.0053162 -0.034053 -1.2516E-05" rpy="0 0 0" />
            <mass value="0.12103" />
            <inertia ixx="2.2715E-05" ixy="-4.8507E-09" ixz="3.0375E-09" iyy="2.1891E-05" iyz="-7.5024E-09" izz="1.9579E-05" />
        </inertial>

        <visual>
            <origin xyz="0 0 0" rpy="0 0 0" />
            <geometry>
                <mesh filename="package://arm_description/meshes/Link5.STL" />
            </geometry>
            <material name="">
                <color rgba="0.25098 0.25098 0.25098 1" />
            </material>
        </visual>
        <collision>
            <origin xyz="0 0 0" rpy="0 0 0" />
            <geometry>
                <mesh filename="package://arm_description/meshes/Link5.STL" />
            </geometry>
        </collision>
    </link>
    <joint name="J5" type="revolute">
        <origin xyz="0.1873 0.034781 0" rpy="0 0 0" />
        <parent link="Link4" />
        <child link="Link5" />
        <axis xyz="0 -1 0" />
        <limit lower="-3.14" upper="3.14" effort="1" velocity="0.2" />
        <dynamics damping="0.5" friction="0.5" />
    </joint>
    <link name="EE">
        
<inertial>
            <origin xyz="0.014612 -5.3033E-07 0.069029" rpy="0 0 0" />
            <mass value="0.10423" />
            <inertia ixx="0.00012008" ixy="-1.8069E-08" ixz="1.8028E-05" iyy="0.00013591" iyz="2.1569E-08" izz="0.00010079" />
        </inertial>

        <visual>
            <origin xyz="0 0 0" rpy="0 0 0" />
            <geometry>
                <mesh filename="package://arm_description/meshes/EE.STL" />
            </geometry>
            <material name="">
                <color rgba="0.79216 0.81961 0.93333 1" />
            </material>
        </visual>
        <collision>
            <origin xyz="0 0 0" rpy="0 0 0" />
            <geometry>
                <mesh filename="package://arm_description/meshes/EE.STL" />
            </geometry>
        </collision>
    </link>
    <joint name="J6" type="revolute">
        <origin xyz="0.0129 -0.035781 0" rpy="0 0 0" />
        <parent link="Link5" />
        <child link="EE" />
        <axis xyz="1 0 0" />
        <limit lower="-3.14" upper="3.14" effort="1" velocity="0.2" />
         <dynamics damping="0.5" friction="0.5" /> 
    </joint>
    <link name="Connector">
        
<inertial>
            <origin xyz="-0.001369 -7.9653E-05 0.024618" rpy="0 0 0" />
            <mass value="0.098251" />
            <inertia ixx="9.9071E-05" ixy="9.9525E-09" ixz="-3.1379E-05" iyy="0.00024297" iyz="3.2777E-07" izz="0.00023545" />
        </inertial>

        <visual>
            <origin xyz="0 0 0" rpy="0 0 0" />
            <geometry>
                <mesh filename="package://arm_description/meshes/Connector.STL" />
            </geometry>
            <material name="">
                <color rgba="0.79216 0.81961 0.93333 1" />
            </material>
        </visual>
        <collision>
            <origin xyz="0 0 0" rpy="0 0 0" />
            <geometry>
                <mesh filename="package://arm_description/meshes/Connector.STL" />
            </geometry>
        </collision>
    </link>
    <joint name="Connector_joint" type="fixed">
        <origin xyz="0.050145 0 0.098" rpy="0 0 0" />
        <parent link="EE" />
        <child link="Connector" />
        <axis xyz="0 0 0" />
    </joint>
    
<transmission name="trans_J1">
        <type>transmission_interface/SimpleTransmission</type>
        <joint name="J1">
            <hardwareInterface>hardware_interface/EffortJointInterface</hardwareInterface>
        </joint>
        <actuator name="J1_motor">
            <hardwareInterface>hardware_interface/EffortJointInterface</hardwareInterface>
            <mechanicalReduction>1</mechanicalReduction>
        </actuator>
    </transmission>
    <transmission name="trans_J2">
        <type>transmission_interface/SimpleTransmission</type>
        <joint name="J2">
            <hardwareInterface>hardware_interface/EffortJointInterface</hardwareInterface>
        </joint>
        <actuator name="J2_motor">
            <hardwareInterface>hardware_interface/EffortJointInterface</hardwareInterface>
            <mechanicalReduction>1</mechanicalReduction>
        </actuator>
    </transmission>
    <transmission name="trans_J3">
        <type>transmission_interface/SimpleTransmission</type>
        <joint name="J3">
            <hardwareInterface>hardware_interface/EffortJointInterface</hardwareInterface>
        </joint>
        <actuator name="J3_motor">
            <hardwareInterface>hardware_interface/EffortJointInterface</hardwareInterface>
            <mechanicalReduction>1</mechanicalReduction>
        </actuator>
    </transmission>
    <transmission name="trans_J4">
        <type>transmission_interface/SimpleTransmission</type>
        <joint name="J4">
            <hardwareInterface>hardware_interface/EffortJointInterface</hardwareInterface>
        </joint>
        <actuator name="J4_motor">
            <hardwareInterface>hardware_interface/EffortJointInterface</hardwareInterface>
            <mechanicalReduction>1</mechanicalReduction>
        </actuator>
    </transmission>
    <transmission name="trans_J5">
        <type>transmission_interface/SimpleTransmission</type>
        <joint name="J5">
            <hardwareInterface>hardware_interface/EffortJointInterface</hardwareInterface>
        </joint>
        <actuator name="J5_motor">
            <hardwareInterface>hardware_interface/EffortJointInterface</hardwareInterface>
            <mechanicalReduction>1</mechanicalReduction>
        </actuator>
    </transmission>
    <transmission name="trans_J6">
        <type>transmission_interface/SimpleTransmission</type>
        <joint name="J6">
            <hardwareInterface>hardware_interface/EffortJointInterface</hardwareInterface>
        </joint>
        <actuator name="J6_motor">
            <hardwareInterface>hardware_interface/EffortJointInterface</hardwareInterface>
            <mechanicalReduction>1</mechanicalReduction>
        </actuator>
    </transmission>

<gazebo reference="base_link">
    
    <turnGravityOff>true</turnGravityOff>
    <selfCollide>True</selfCollide>
</gazebo>
<gazebo reference="Link0">
    <turnGravityOff>true</turnGravityOff>
    <selfCollide>True</selfCollide>
</gazebo>
<gazebo reference="Link1">
    <turnGravityOff>true</turnGravityOff>
    <selfCollide>True</selfCollide>
</gazebo>
<gazebo reference="Link2">
    <turnGravityOff>true</turnGravityOff>
    <selfCollide>True</selfCollide>
</gazebo>
<gazebo reference="Link3">
    <turnGravityOff>true</turnGravityOff>
    <selfCollide>True</selfCollide>
</gazebo>
<gazebo reference="Link4">
    <turnGravityOff>true</turnGravityOff>
    <selfCollide>True</selfCollide>
</gazebo>
 <gazebo reference="Link5">
    <turnGravityOff>true</turnGravityOff>
    <selfCollide>True</selfCollide>
</gazebo>
 <gazebo reference="EE">
   <turnGravityOff>true</turnGravityOff>
    <selfCollide>True</selfCollide>
</gazebo>


<gazebo reference="J1">
    <provideFeedback>True</provideFeedback>
    <implicitSpringDamper>True</implicitSpringDamper>
</gazebo>
<gazebo reference="J2">
    <provideFeedback>True</provideFeedback>
    <implicitSpringDamper>True</implicitSpringDamper>
</gazebo>
<gazebo reference="J3">
    <implicitSpringDamper>True</implicitSpringDamper>
</gazebo>
<gazebo reference="J4">
    <implicitSpringDamper>True</implicitSpringDamper>
</gazebo>
<gazebo reference="J5">
    <implicitSpringDamper>True</implicitSpringDamper>
</gazebo>
<gazebo reference="J6">
    <implicitSpringDamper>True</implicitSpringDamper>
</gazebo>


</robot>
