<?xml version="1.0" encoding="utf-8" ?>
<!-- This URDF was automatically created by SolidWorks to URDF Exporter! Originally created by Stephen Brawner (brawner@gmail.com) 
     Commit Version: 1.5.1-0-g916b5db  Build Version: 1.5.7152.31018
     For more information, please see http://wiki.ros.org/sw_urdf_exporter -->
<robot name="arm_description">

    <link name="world">
    </link>


 
	<link name="base_link">
        <gravity> 0 </gravity>
<inertial>
            <origin xyz="-1.15397205339615E-05 -0.10213687957753 0.0256683807735144" rpy="0 0 0" />
            <mass value="0.66695527839868" />
            <inertia ixx="0.00200785375472586" ixy="8.95894771130143E-07" ixz="-4.55457901869221E-07" iyy="0.0015409663357719" iyz="5.63870746638963E-05" izz="0.00329186572157014" />
        </inertial>

        <visual>
            <origin xyz="0 0 0" rpy="0 0 0" />
            <geometry>
                <mesh filename="package://arm_description/meshes/base_link.STL" />
            </geometry>
            <material name="">
                <color rgba="1 1 1 1" />
            </material>
        </visual>
        <collision>
            <origin xyz="0 0 0" rpy="0 0 0" />
            <geometry>
                <mesh filename="package://arm_description/meshes/base_link.STL" />
            </geometry>
        </collision>
    </link>
 
 
     <joint name="fixed" type="fixed">
        <origin xyz="0 0 0"  />
        <parent link="world" />
        <child link="base_link" />
    </joint>

 
 
    <link name="Link1">
<inertial>
            <origin xyz="0.032141 -0.0063693 -0.020838" rpy="0 0 0" />
            <mass value="0.51011" />
            <inertia ixx="0.00048671" ixy="-4.2616E-06" ixz="3.5903E-05" iyy="0.00065864" iyz="2.2456E-06" izz="0.0005653" />
        </inertial>

        <visual>
            <origin xyz="0 0 0" rpy="0 0 0" />
            <geometry>
                <mesh filename="package://arm_description/meshes/Link1.STL" />
            </geometry>
            <material name="">
                <color rgba="0.66667 0.69804 0.76863 1" />
            </material>
        </visual>
        <collision>
            <origin xyz="0 0 0" rpy="0 0 0" />
            <geometry>
                <mesh filename="package://arm_description/meshes/Link1.STL" />
            </geometry>
        </collision>
    </link>
    <joint name="J1" type="revolute">
        <origin xyz="0 0 0.0867" rpy="3.1416 0 1.5708" />
        <parent link="base_link" />
        <child link="Link1" />
        <axis xyz="0 0 1" />
        <limit lower="-3.141593" upper="3.141593" effort="0" velocity="0.2" />
    </joint>


    <link name="Link2">
<inertial>
            <origin xyz="0.080422 -0.13477 -0.053585" rpy="0 0 0" />
            <mass value="0.53035" />
            <inertia ixx="0.0020434" ixy="0.0010489" ixz="1.664E-07" iyy="0.00084612" iyz="-8.1845E-08" izz="0.0028454" />
        </inertial>

        <visual>
            <origin xyz="0 0 0" rpy="0 0 0" />
            <geometry>
                <mesh filename="package://arm_description/meshes/Link2.STL" />
            </geometry>
            <material name="">
                <color rgba="0.66667 0.69804 0.76863 1" />
            </material>
        </visual>
        <collision>
            <origin xyz="0 0 0" rpy="0 0 0" />
            <geometry>
                <mesh filename="package://arm_description/meshes/Link2.STL" />
            </geometry>
        </collision>
    </link>
    <joint name="J2" type="revolute">
        <origin xyz="0.064146 -0.007968 -0.083075" rpy="1.5708 0.5236 3.1416" />
        <parent link="Link1" />
        <child link="Link2" />
        <axis xyz="0 0 1" />
        <limit lower="-3.141593" upper="3.141593" effort="0" velocity="0.2" />
    </joint>


    <link name="Link3">
<inertial>
            <origin xyz="-0.00102555575202164 -0.00387982974471979 -0.0464271182276246" rpy="0 0 0" />
            <mass value="0.139370701456675" />
            <inertia ixx="4.7707018460657E-05" ixy="-1.11304367458891E-08" ixz="2.21188897459325E-06" iyy="7.90931093716717E-05" iyz="2.06183684225396E-07" izz="6.96384643549249E-05" />
        </inertial>

        <visual>
            <origin xyz="0 0 0" rpy="0 0 0" />
            <geometry>
                <mesh filename="package://arm_description/meshes/Link3.STL" />
            </geometry>
            <material name="">
                <color rgba="0.752941176470588 0.752941176470588 0.752941176470588 1" />
            </material>
        </visual>
        <collision>
            <origin xyz="0 0 0" rpy="0 0 0" />
            <geometry>
                <mesh filename="package://arm_description/meshes/Link3.STL" />
            </geometry>
        </collision>
    </link>
    <joint name="J3" type="revolute">
        <origin xyz="0.1525 -0.26414 -0.043745" rpy="3.1263 0 0.5236" />
        <parent link="Link2" />
        <child link="Link3" />
        <axis xyz="0 0.01527 -0.99988" />
        <limit lower="-3.141593" upper="3.141593" effort="0" velocity="0.2" />
    </joint>


    <link name="Link4">
<inertial>
            <origin xyz="-0.00392412669689435 0.00112688757108009 0.090746722191295" rpy="0 0 0" />
            <mass value="0.290695240644425" />
            <inertia ixx="0.000575263509263945" ixy="-2.22197708945538E-06" ixz="4.62059886126857E-06" iyy="0.000516200265723224" iyz="1.48107971263623E-05" izz="0.000101002671430719" />
        </inertial>

        <visual>
            <origin xyz="0 0 0" rpy="0 0 0" />
            <geometry>
                <mesh filename="package://arm_description/meshes/Link4.STL" />
            </geometry>
            <material name="">
                <color rgba="0.666666666666667 0.698039215686274 0.768627450980392 1" />
            </material>
        </visual>
        <collision>
            <origin xyz="0 0 0" rpy="0 0 0" />
            <geometry>
                <mesh filename="package://arm_description/meshes/Link4.STL" />
            </geometry>
        </collision>
    </link>
    <joint name="J4" type="revolute">
        <origin xyz="-0.035639 0.00078946 -0.051694" rpy="1.5708 -1.5555 -1.5708" />
        <parent link="Link3" />
        <child link="Link4" />
        <axis xyz="0 0 -1" />
        <limit lower="-3.141593" upper="3.141593" effort="0" velocity="0.2" />
    </joint>
    
<transmission name="trans_J1">
        <type>transmission_interface/SimpleTransmission</type>
        <joint name="J1">
            <hardwareInterface>hardware_interface/EffortJointInterface</hardwareInterface>
        </joint>
        <actuator name="J1_motor">
            <hardwareInterface>hardware_interface/EffortJointInterface</hardwareInterface>
            <mechanicalReduction>1</mechanicalReduction>
        </actuator>
    </transmission>
    <transmission name="trans_J2">
        <type>transmission_interface/SimpleTransmission</type>
        <joint name="J2">
            <hardwareInterface>hardware_interface/EffortJointInterface</hardwareInterface>
        </joint>
        <actuator name="J2_motor">
            <hardwareInterface>hardware_interface/EffortJointInterface</hardwareInterface>
            <mechanicalReduction>1</mechanicalReduction>
        </actuator>
    </transmission>
    <transmission name="trans_J3">
        <type>transmission_interface/SimpleTransmission</type>
        <joint name="J3">
            <hardwareInterface>hardware_interface/EffortJointInterface</hardwareInterface>
        </joint>
        <actuator name="J3_motor">
            <hardwareInterface>hardware_interface/EffortJointInterface</hardwareInterface>
            <mechanicalReduction>1</mechanicalReduction>
        </actuator>
    </transmission>
    <transmission name="trans_J4">
        <type>transmission_interface/SimpleTransmission</type>
        <joint name="J4">
            <hardwareInterface>hardware_interface/EffortJointInterface</hardwareInterface>
        </joint>
        <actuator name="J4_motor">
            <hardwareInterface>hardware_interface/EffortJointInterface</hardwareInterface>
            <mechanicalReduction>1</mechanicalReduction>
        </actuator>
    </transmission>
    <gazebo>
	    <plugin name="gazebo_ros_control" filename="libgazebo_ros_control.so">
	   <robotNamespace>/</robotNamespace>
           </plugin>    
    </gazebo>

    <gazebo reference="base_link">
        <turnGravityOff>true</turnGravityOff>
    </gazebo>
    <gazebo reference="Link1">
        <turnGravityOff>true</turnGravityOff>
    </gazebo>
    <gazebo reference="Link2">
        <turnGravityOff>true</turnGravityOff>
    </gazebo>
    <gazebo reference="Link3">
        <turnGravityOff>true</turnGravityOff>
    </gazebo>
    <gazebo reference="Link4">
        <turnGravityOff>true</turnGravityOff>
    </gazebo>
</robot>
